Workbook
Name sydney_camera_list_201409262229_1: Sydney!$A$1:$N$89

Sheet London
A1: identifier | B1: version | C1: publishDateTime | D1: author | E1: owner | F1: refreshRate | G1: max_Latency | H1: timeToError | I1: overrideMessage | J1: errorMessage | K1: feedInfo | L1: logo | M1: updated | N1: rooturl | O1: id | P1: available | Q1: corridor | R1: location | S1: currentView | T1: file | U1: captureTime | V1: easting | W1: northing | X1: lat | Y1: lng | Z1: osgr | AA1: postCode | AB1: unavailabilityCause | AC1: Column1 | AD1: Column2
A2: TfL Traffic Cameras | B2: 0.1 | C2: 2014-09-24T09:54:17Z | D2: digital@tfl.gov.uk | E2: Transport for London | F2: 1 | G2: 10 | H2: 10 | L2: http://www.tfl.gov.uk/tfl-global/images/roundel.gif | M2: 1411552457 | N2: /tfl/livetravelnews/trafficcams/cctv/ | O2: 1.01251 | P2: TRUE | R2: Old Street e of Vince St | T2: 0000101251.jpg | U2: 2014-09-24T09:52:00Z | V2: 532899 | W2: 182552 | X2: 51.52625 | Y2: -0.08563431 | Z2: TQ329826 | AA2: EC1V 9HB | AC2: ="http://tfl.gov.uk/tfl/livetravelnews/trafficcams/cctv/" & Table1[[#This Row],[file]] -> http://tfl.gov.uk/tfl/livetravelnews/trafficcams/cctv/0000101251.jpg | AD2: ="insert into webcam select name = '"&Table1[[#This Row],[location]]&"', xcoord = "&Table1[[#This Row],[lng]]&", ycoord = "&Table1[[#This Row],[lat]]&", url = '"&Table1[[#This Row],[Column1]]&"', radiusofvisibility = 100" -> insert into webcam select name = 'Old Street e of Vince St', xcoord = -0.08563431, ycoord = 51.52625, url = 'http://tfl.gov.uk/tfl/livetravelnews/trafficcams/cctv/0000101251.jpg', radiusofvisibility = 100
A3: TfL Traffic Cameras | B3: 0.1 | C3: 2014-09-24T09:54:17Z | D3: digital@tfl.gov.uk | E3: Transport for London | F3: 1 | G3: 10 | H3: 10 | L3: http://www.tfl.gov.uk/tfl-global/images/roundel.gif | M3: 1411552457 | N3: /tfl/livetravelnews/trafficcams/cctv/ | O3: 1.01252 | P3: FALSE | R3: Curtain Rd / Old Street | T3: 0000101252.jpg | U3: 1970-01-01T00:00:00Z | V3: 533252 | W3: 182647 | X3: 51.52702 | Y3: -0.08051296 | Z3: TQ333826 | AA3: EC1V 9LE | AB3: Unavailable due to camera fault | AC3: ="http://tfl.gov.uk/tfl/livetravelnews/trafficcams/cctv/" & Table1[[#This Row],[file]] -> http://tfl.gov.uk/tfl/livetravelnews/trafficcams/cctv/0000101252.jpg | AD3: ="insert into webcam select name = '"&Table1[[#This Row],[location]]&"', xcoord = "&Table1[[#This Row],[lng]]&", ycoord = "&Table1[[#This Row],[lat]]&", url = '"&Table1[[#This Row],[Column1]]&"', radiusofvisibility = 100" -> insert into webcam select name = 'Curtain Rd / Old Street', xcoord = -0.08051296, ycoord = 51.52702, url = 'http://tfl.gov.uk/tfl/livetravelnews/trafficcams/cctv/0000101252.jpg', radiusofvisibility = 100
A4: TfL Traffic Cameras | B4: 0.1 | C4: 2014-09-24T09:54:17Z | D4: digital@tfl.gov.uk | E4: Transport for London | F4: 1 | G4: 10 | H4: 10 | L4: http://www.tfl.gov.uk/tfl-global/images/roundel.gif | M4: 1411552457 | N4: /tfl/livetravelnews/trafficcams/cctv/ | O4: 1.0126 | P4: TRUE | R4: Old Street/Gt Eastern St | T4: 0000101260.jpg | U4: 2014-09-24T09:52:28Z | V4: 533002 | W4: 182580 | X4: 51.526478 | Y4: -0.08413989 | Z4: TQ330826 | AA4: EC1V 9EY | AC4: ="http://tfl.gov.uk/tfl/livetravelnews/trafficcams/cctv/" & Table1[[#This Row],[file]] -> http://tfl.gov.uk/tfl/livetravelnews/trafficcams/cctv/0000101260.jpg | AD4: ="insert into webcam select name = '"&Table1[[#This Row],[location]]&"', xcoord = "&Table1[[#This Row],[lng]]&", ycoord = "&Table1[[#This Row],[lat]]&", url = '"&Table1[[#This Row],[Column1]]&"', radiusofvisibility = 100" -> insert into webcam select name = 'Old Street/Gt Eastern St', xcoord = -0.08413989, ycoord = 51.526478, url = 'http://tfl.gov.uk/tfl/livetravelnews/trafficcams/cctv/0000101260.jpg', radiusofvisibility = 100
A5: TfL Traffic Cameras | B5: 0.1 | C5: 2014-09-24T09:54:17Z | D5: digital@tfl.gov.uk | E5: Transport for London | F5: 1 | G5: 10 | H5: 10 | L5: http://www.tfl.gov.uk/tfl-global/images/roundel.gif | M5: 1411552457 | N5: /tfl/livetravelnews/trafficcams/cctv/ | O5: 1.01301 | P5: TRUE | R5: Gt Eastern St/Curtain Rd | T5: 0000101301.jpg | U5: 2014-09-24T09:53:35Z | V5: 533276 | W5: 182355 | X5: 51.52439 | Y5: -0.08027758 | Z5: TQ333824 | AA5: EC2A 3ES | AC5: ="http://tfl.gov.uk/tfl/livetravelnews/trafficcams/cctv/" & Table1[[#This Row],[file]] -> http://tfl.gov.uk/tfl/livetravelnews/trafficcams/cctv/0000101301.jpg | AD5: ="insert into webcam select name = '"&Table1[[#This Row],[location]]&"', xcoord = "&Table1[[#This Row],[lng]]&", ycoord = "&Table1[[#This Row],[lat]]&", url = '"&Table1[[#This Row],[Column1]]&"', radiusofvisibility = 100" -> insert into webcam select name = 'Gt Eastern St/Curtain Rd', xcoord = -0.08027758, ycoord = 51.52439, url = 'http://tfl.gov.uk/tfl/livetravelnews/trafficcams/cctv/0000101301.jpg', radiusofvisibility = 100
A6: TfL Traffic Cameras | B6: 0.1 | C6: 2014-09-24T09:54:17Z | D6: digital@tfl.gov.uk | E6: Transport for London | F6: 1 | G6: 10 | H6: 10 | L6: http://www.tfl.gov.uk/tfl-global/images/roundel.gif | M6: 1411552457 | N6: /tfl/livetravelnews/trafficcams/cctv/ | O6: 1.01302 | P6: TRUE | R6: Gt Eastern St/Holywell Ln | T6: 0000101302.jpg | U6: 2014-09-24T09:53:49Z | V6: 533307 | W6: 182325 | X6: 51.524117 | Y6: -0.079842344 | Z6: TQ333823 | AA6: EC2A 3ES | AC6: ="http://tfl.gov.uk/tfl/livetravelnews/trafficcams/cctv/" & Table1[[#This Row],[file]] -> http://tfl.gov.uk/tfl/livetravelnews/trafficcams/cctv/0000101302.jpg | AD6: ="insert into webcam select name = '"&Table1[[#This Row],[location]]&"', xcoord = "&Table1[[#This Row],[lng]]&", ycoord = "&Table1[[#This Row],[lat]]&", url = '"&Table1[[#This Row],[Column1]]&"', radiusofvisibility = 100" -> insert into webcam select name = 'Gt Eastern St/Holywell Ln', xcoord = -0.079842344, ycoord = 51.524117, url = 'http://tfl.gov.uk/tfl/livetravelnews/trafficcams/cctv/0000101302.jpg', radiusofvisibility = 100
A7: TfL Traffic Cameras | B7: 0.1 | C7: 2014-09-24T09:54:17Z | D7: digital@tfl.gov.uk | E7: Transport for London | F7: 1 | G7: 10 | H7: 10 | L7: http://www.tfl.gov.uk/tfl-global/images/roundel.gif | M7: 1411552457 | N7: /tfl/livetravelnews/trafficcams/cctv/ | O7: 1.0135 | P7: TRUE | R7: East Road/Vestry Street | T7: 0000101350.jpg | U7: 2014-09-24T09:52:14Z | V7: 532789 | W7: 182931 | X7: 51.529682 | Y7: -0.08707626 | Z7: TQ328829 | AA7: N1 6AW | AC7: ="http://tfl.gov.uk/tfl/livetravelnews/trafficcams/cctv/" & Table1[[#This Row],[file]] -> http://tfl.gov.uk/tfl/livetravelnews/trafficcams/cctv/0000101350.jpg | AD7: ="insert into webcam select name = '"&Table1[[#This Row],[location]]&"', xcoord = "&Table1[[#This Row],[lng]]&", ycoord = "&Table1[[#This Row],[lat]]&", url = '"&Table1[[#This Row],[Column1]]&"', radiusofvisibility = 100" -> insert into webcam select name = 'East Road/Vestry Street', xcoord = -0.08707626, ycoord = 51.529682, url = 'http://tfl.gov.uk/tfl/livetravelnews/trafficcams/cctv/0000101350.jpg', radiusofvisibility = 100
A8: TfL Traffic Cameras | B8: 0.1 | C8: 2014-09-24T09:54:17Z | D8: digital@tfl.gov.uk | E8: Transport for London | F8: 1 | G8: 10 | H8: 10 | L8: http://www.tfl.gov.uk/tfl-global/images/roundel.gif | M8: 1411552457 | N8: /tfl/livetravelnews/trafficcams/cctv/ | O8: 1.014 | P8: FALSE | R8: Shoreditch High St/Commercial St | T8: 0000101400.jpg | U8: 1970-01-01T00:00:00Z | V8: 533465 | W8: 182187 | X8: 51.52284 | Y8: -0.07761848 | Z8: TQ335822 | AA8: E1 6BW | AB8: Unavailable due to camera fault | AC8: ="http://tfl.gov.uk/tfl/livetravelnews/trafficcams/cctv/" & Table1[[#This Row],[file]] -> http://tfl.gov.uk/tfl/livetravelnews/trafficcams/cctv/0000101400.jpg | AD8: ="insert into webcam select name = '"&Table1[[#This Row],[location]]&"', xcoord = "&Table1[[#This Row],[lng]]&", ycoord = "&Table1[[#This Row],[lat]]&", url = '"&Table1[[#This Row],[Column1]]&"', radiusofvisibility = 100" -> insert into webcam select name = 'Shoreditch High St/Commercial St', xcoord = -0.07761848, ycoord = 51.52284, url = 'http://tfl.gov.uk/tfl/livetravelnews/trafficcams/cctv/0000101400.jpg', radiusofvisibility = 100
A9: TfL Traffic Cameras | B9: 0.1 | C9: 2014-09-24T09:54:17Z | D9: digital@tfl.gov.uk | E9: Transport for London | F9: 1 | G9: 10 | H9: 10 | L9: http://www.tfl.gov.uk/tfl-global/images/roundel.gif | M9: 1411552457 | N9: /tfl/livetravelnews/trafficcams/cctv/ | O9: 1.01401 | P9: FALSE | R9: A10 North of Holywell Ln | T9: 0000101401.jpg | U9: 1970-01-01T00:00:00Z | V9: 533486 | W9: 182301 | X9: 51.523857 | Y9: -0.07727282 | Z9: TQ335823 | AA9: EC2A 3ET | AB9: Unavailable due to camera fault | AC9: ="http://tfl.gov.uk/tfl/livetravelnews/trafficcams/cctv/" & Table1[[#This Row],[file]] -> http://tfl.gov.uk/tfl/livetravelnews/trafficcams/cctv/0000101401.jpg | AD9: ="insert into webcam select name = '"&Table1[[#This Row],[location]]&"', xcoord = "&Table1[[#This Row],[lng]]&", ycoord = "&Table1[[#This Row],[lat]]&", url = '"&Table1[[#This Row],[Column1]]&"', radiusofvisibility = 100" -> insert into webcam select name = 'A10 North of Holywell Ln', xcoord = -0.07727282, ycoord = 51.523857, url = 'http://tfl.gov.uk/tfl/livetravelnews/trafficcams/cctv/0000101401.jpg', radiusofvisibility = 100
A10: TfL Traffic Cameras | B10: 0.1 | C10: 2014-09-24T09:54:17Z | D10: digital@tfl.gov.uk | E10: Transport for London | F10: 1 | G10: 10 | H10: 10 | L10: http://www.tfl.gov.uk/tfl-global/images/roundel.gif | M10: 1411552457 | N10: /tfl/livetravelnews/trafficcams/cctv/ | O10: 1.01402 | P10: TRUE | R10: Kingsland Rd/Hackney Rd | T10: 0000101402.jpg | U10: 2014-09-24T09:53:30Z | V10: 533427 | W10: 182695 | X10: 51.527412 | Y10: -0.07797365 | Z10: TQ334827 | AA10: EC1V 9LP | AC10: ="http://tfl.gov.uk/tfl/livetravelnews/trafficcams/cctv/" & Table1[[#This Row],[file]] -> http://tfl.gov.uk/tfl/livetravelnews/trafficcams/cctv/0000101402.jpg | AD10: ="insert into webcam select name = '"&Table1[[#This Row],[location]]&"', xcoord = "&Table1[[#This Row],[lng]]&", ycoord = "&Table1[[#This Row],[lat]]&", url = '"&Table1[[#This Row],[Column1]]&"', radiusofvisibility = 100" -> insert into webcam select name = 'Kingsland Rd/Hackney Rd', xcoord = -0.07797365, ycoord = 51.527412, url = 'http://tfl.gov.uk/tfl/livetravelnews/trafficcams/cctv/0000101402.jpg', radiusofvisibility = 100
A11: TfL Traffic Cameras | B11: 0.1 | C11: 2014-09-24T09:54:17Z | D11: digital@tfl.gov.uk | E11: Transport for London | F11: 1 | G11: 10 | H11: 10 | L11: http://www.tfl.gov.uk/tfl-global/images/roundel.gif | M11: 1411552457 | N11: /tfl/livetravelnews/trafficcams/cctv/ | O11: 1.01403 | P11: TRUE | R11: A10 North of Waterson St | T11: 0000101403.jpg | U11: 2014-09-24T09:53:22Z | V11: 533439 | W11: 182866 | X11: 51.528946 | Y11: -0.07773605 | Z11: TQ334829 | AA11: E2 8HE | AC11: ="http://tfl.gov.uk/tfl/livetravelnews/trafficcams/cctv/" & Table1[[#This Row],[file]] -> http://tfl.gov.uk/tfl/livetravelnews/trafficcams/cctv/0000101403.jpg | AD11: ="insert into webcam select name = '"&Table1[[#This Row],[location]]&"', xcoord = "&Table1[[#This Row],[lng]]&", ycoord = "&Table1[[#This Row],[lat]]&", url = '"&Table1[[#This Row],[Column1]]&"', radiusofvisibility = 100" -> insert into webcam select name = 'A10 North of Waterson St', xcoord = -0.07773605, ycoord = 51.528946, url = 'http://tfl.gov.uk/tfl/livetravelnews/trafficcams/cctv/0000101403.jpg', radiusofvisibility = 100
A12: TfL Traffic Cameras | B12: 0.1 | C12: 2014-09-24T09:54:17Z | D12: digital@tfl.gov.uk | E12: Transport for London | F12: 1 | G12: 10 | H12: 10 | L12: http://www.tfl.gov.uk/tfl-global/images/roundel.gif | M12: 1411552457 | N12: /tfl/livetravelnews/trafficcams/cctv/ | O12: 1.01404 | P12: TRUE | R12: A10 North of Shenfield St | T12: 0000101404.jpg | U12: 2014-09-24T09:53:34Z | V12: 533484 | W12: 183120 | X12: 51.531216 | Y12: -0.07699154 | Z12: TQ335831 | AA12: N1 6RY | AC12: ="http://tfl.gov.uk/tfl/livetravelnews/trafficcams/cctv/" & Table1[[#This Row],[file]] -> http://tfl.gov.uk/tfl/livetravelnews/trafficcams/cctv/0000101404.jpg | AD12: ="insert into webcam select name = '"&Table1[[#This Row],[location]]&"', xcoord = "&Table1[[#This Row],[lng]]&", ycoord = "&Table1[[#This Row],[lat]]&", url = '"&Table1[[#This Row],[Column1]]&"', radiusofvisibility = 100" -> insert into webcam select name = 'A10 North of Shenfield St', xcoord = -0.07699154, ycoord = 51.531216, url = 'http://tfl.gov.uk/tfl/livetravelnews/trafficcams/cctv/0000101404.jpg', radiusofvisibility = 100
A13: TfL Traffic Cameras | B13: 0.1 | C13: 2014-09-24T09:54:17Z | D13: digital@tfl.gov.uk | E13: Transport for London | F13: 1 | G13: 10 | H13: 10 | L13: http://www.tfl.gov.uk/tfl-global/images/roundel.gif | M13: 1411552457 | N13: /tfl/livetravelnews/trafficcams/cctv/ | O13: 1.01405 | P13: TRUE | R13: A10 South of Pearson St | T13: 0000101405.jpg | U13: 2014-09-24T09:52:04Z | V13: 533476 | W13: 183299 | X13: 51.53283 | Y13: -0.07703902 | Z13: TQ335833 | AA13: E2 8DY | AC13: ="http://tfl.gov.uk/tfl/livetravelnews/trafficcams/cctv/" & Table1[[#This Row],[file]] -> http://tfl.gov.uk/tfl/livetravelnews/trafficcams/cctv/0000101405.jpg | AD13: ="insert into webcam select name = '"&Table1[[#This Row],[location]]&"', xcoord = "&Table1[[#This Row],[lng]]&", ycoord = "&Table1[[#This Row],[lat]]&", url = '"&Table1[[#This Row],[Column1]]&"', radiusofvisibility = 100" -> insert into webcam select name = 'A10 South of Pearson St', xcoord = -0.07703902, ycoord = 51.53283, url = 'http://tfl.gov.uk/tfl/livetravelnews/trafficcams/cctv/0000101405.jpg', radiusofvisibility = 100
A14: TfL Traffic Cameras | B14: 0.1 | C14: 2014-09-24T09:54:17Z | D14: digital@tfl.gov.uk | E14: Transport for London | F14: 1 | G14: 10 | H14: 10 | L14: http://www.tfl.gov.uk/tfl-global/images/roundel.gif | M14: 1411552457 | N14: /tfl/livetravelnews/trafficcams/cctv/ | O14: 1.01406 | P14: FALSE | R14: A10 South of Laburnum St | T14: 0000101406.jpg | U14: 1970-01-01T00:00:00Z | V14: 533481 | W14: 183531 | X14: 51.534912 | Y14: -0.07687911 | Z14: TQ335835 | AA14: E2 8AJ | AB14: In use keeping London moving | AC14: ="http://tfl.gov.uk/tfl/livetravelnews/trafficcams/cctv/" & Table1[[#This Row],[file]] -> http://tfl.gov.uk/tfl/livetravelnews/trafficcams/cctv/0000101406.jpg | AD14: ="insert into webcam select name = '"&Table1[[#This Row],[location]]&"', xcoord = "&Table1[[#This Row],[lng]]&", ycoord = "&Table1[[#This Row],[lat]]&", url = '"&Table1[[#This Row],[Column1]]&"', radiusofvisibility = 100" -> insert into webcam select name = 'A10 South of Laburnum St', xcoord = -0.07687911, ycoord = 51.534912, url = 'http://tfl.gov.uk/tfl/livetravelnews/trafficcams/cctv/0000101406.jpg', radiusofvisibility = 100
A15: TfL Traffic Cameras | B15: 0.1 | C15: 2014-09-24T09:54:17Z | D15: digital@tfl.gov.uk | E15: Transport for London | F15: 1 | G15: 10 | H15: 10 | L15: http://www.tfl.gov.uk/tfl-global/images/roundel.gif | M15: 1411552457 | N15: /tfl/livetravelnews/trafficcams/cctv/ | O15: 1.01407 | P15: TRUE | R15: A10 North of Lee Street | T15: 0000101407.jpg | U15: 2014-09-24T09:53:44Z | V15: 533472 | W15: 183937 | X15: 51.538563 | Y15: -0.076855004 | Z15: TQ335839 | AA15: E8 4DL | AC15: ="http://tfl.gov.uk/tfl/livetravelnews/trafficcams/cctv/" & Table1[[#This Row],[file]] -> http://tfl.gov.uk/tfl/livetravelnews/trafficcams/cctv/0000101407.jpg | AD15: ="insert into webcam select name = '"&Table1[[#This Row],[location]]&"', xcoord = "&Table1[[#This Row],[lng]]&", ycoord = "&Table1[[#This Row],[lat]]&", url = '"&Table1[[#This Row],[Column1]]&"', radiusofvisibility = 100" -> insert into webcam select name = 'A10 North of Lee Street', xcoord = -0.076855004, ycoord = 51.538563, url = 'http://tfl.gov.uk/tfl/livetravelnews/trafficcams/cctv/0000101407.jpg', radiusofvisibility = 100
A16: TfL Traffic Cameras | B16: 0.1 | C16: 2014-09-24T09:54:17Z | D16: digital@tfl.gov.uk | E16: Transport for London | F16: 1 | G16: 10 | H16: 10 | L16: http://www.tfl.gov.uk/tfl-global/images/roundel.gif | M16: 1411552457 | N16: /tfl/livetravelnews/trafficcams/cctv/ | O16: 1.01408 | P16: TRUE | R16: A10 / Downham Road | T16: 0000101408.jpg | U16: 2014-09-24T09:52:05Z | V16: 533487 | W16: 183992 | X16: 51.53905 | Y16: -0.076618016 | Z16: TQ335840 | AA16: E8 4DB | AC16: ="http://tfl.gov.uk/tfl/livetravelnews/trafficcams/cctv/" & Table1[[#This Row],[file]] -> http://tfl.gov.uk/tfl/livetravelnews/trafficcams/cctv/0000101408.jpg | AD16: ="insert into webcam select name = '"&Table1[[#This Row],[location]]&"', xcoord = "&Table1[[#This Row],[lng]]&", ycoord = "&Table1[[#This Row],[lat]]&", url = '"&Table1[[#This Row],[Column1]]&"', radiusofvisibility = 100" -> insert into webcam select name = 'A10 / Downham Road', xcoord = -0.076618016, ycoord = 51.53905, url = 'http://tfl.gov.uk/tfl/livetravelnews/trafficcams/cctv/0000101408.jpg', radiusofvisibility = 100
A17: TfL Traffic Cameras | B17: 0.1 | C17: 2014-09-24T09:54:17Z | D17: digital@tfl.gov.uk | E17: Transport for London | F17: 1 | G17: 10 | H17: 10 | L17: http://www.tfl.gov.uk/tfl-global/images/roundel.gif | M17: 1411552457 | N17: /tfl/livetravelnews/trafficcams/cctv/ | O17: 1.01409 | P17: TRUE | R17: A10 South of St Peters Way | T17: 0000101409.jpg | U17: 2014-09-24T09:53:13Z | V17: 533478 | W17: 184158 | X17: 51.540546 | Y17: -0.07668481 | Z17: TQ335842 | AA17: N1 5AZ | AC17: ="http://tfl.gov.uk/tfl/livetravelnews/trafficcams/cctv/" & Table1[[#This Row],[file]] -> http://tfl.gov.uk/tfl/livetravelnews/trafficcams/cctv/0000101409.jpg | AD17: ="insert into webcam select name = '"&Table1[[#This Row],[location]]&"', xcoord = "&Table1[[#This Row],[lng]]&", ycoord = "&Table1[[#This Row],[lat]]&", url = '"&Table1[[#This Row],[Column1]]&"', radiusofvisibility = 100" -> insert into webcam select name = 'A10 South of St Peters Way', xcoord = -0.07668481, ycoord = 51.540546, url = 'http://tfl.gov.uk/tfl/livetravelnews/trafficcams/cctv/0000101409.jpg', radiusofvisibility = 100
A18: TfL Traffic Cameras | B18: 0.1 | C18: 2014-09-24T09:54:17Z | D18: digital@tfl.gov.uk | E18: Transport for London | F18: 1 | G18: 10 | H18: 10 | L18: http://www.tfl.gov.uk/tfl-global/images/roundel.gif | M18: 1411552457 | N18: /tfl/livetravelnews/trafficcams/cctv/ | O18: 1.01411 | P18: TRUE | R18: Kingsland Rd/Balls Pond Rd | T18: 0000101411.jpg | U18: 2014-09-24T09:53:34Z | V18: 533532 | W18: 184799 | X18: 51.546295 | Y18: -0.075663626 | Z18: TQ335848 | AA18: E8 2JT | AC18: ="http://tfl.gov.uk/tfl/livetravelnews/trafficcams/cctv/" & Table1[[#This Row],[file]] -> http://tfl.gov.uk/tfl/livetravelnews/trafficcams/cctv/0000101411.jpg | AD18: ="insert into webcam select name = '"&Table1[[#This Row],[location]]&"', xcoord = "&Table1[[#This Row],[lng]]&", ycoord = "&Table1[[#This Row],[lat]]&", url = '"&Table1[[#This Row],[Column1]]&"', radiusofvisibility = 100" -> insert into webcam select name = 'Kingsland Rd/Balls Pond Rd', xcoord = -0.075663626, ycoord = 51.546295, url = 'http://tfl.gov.uk/tfl/livetravelnews/trafficcams/cctv/0000101411.jpg', radiusofvisibility = 100
A19: TfL Traffic Cameras | B19: 0.1 | C19: 2014-09-24T09:54:17Z | D19: digital@tfl.gov.uk | E19: Transport for London | F19: 1 | G19: 10 | H19: 10 | L19: http://www.tfl.gov.uk/tfl-global/images/roundel.gif | M19: 1411552457 | N19: /tfl/livetravelnews/trafficcams/cctv/ | O19: 1.01416 | P19: TRUE | R19: A10 South of Farleigh Rd | T19: 0000101416.jpg | U19: 2014-09-24T09:52:14Z | V19: 533577 | W19: 185744 | X19: 51.554775 | Y19: -0.07465654 | Z19: TQ336857 | AA19: N16 8BX | AC19: ="http://tfl.gov.uk/tfl/livetravelnews/trafficcams/cctv/" & Table1[[#This Row],[file]] -> http://tfl.gov.uk/tfl/livetravelnews/trafficcams/cctv/0000101416.jpg | AD19: ="insert into webcam select name = '"&Table1[[#This Row],[location]]&"', xcoord = "&Table1[[#This Row],[lng]]&", ycoord = "&Table1[[#This Row],[lat]]&", url = '"&Table1[[#This Row],[Column1]]&"', radiusofvisibility = 100" -> insert into webcam select name = 'A10 South of Farleigh Rd', xcoord = -0.07465654, ycoord = 51.554775, url = 'http://tfl.gov.uk/tfl/livetravelnews/trafficcams/cctv/0000101416.jpg', radiusofvisibility = 100
A20: TfL Traffic Cameras | B20: 0.1 | C20: 2014-09-24T09:54:17Z | D20: digital@tfl.gov.uk | E20: Transport for London | F20: 1 | G20: 10 | H20: 10 | L20: http://www.tfl.gov.uk/tfl-global/images/roundel.gif | M20: 1411552457 | N20: /tfl/livetravelnews/trafficcams/cctv/ | O20: 1.01417 | P20: TRUE | R20: A10 North of Walford Rd | T20: 0000101417.jpg | U20: 2014-09-24T09:52:10Z | V20: 533573 | W20: 185867 | X20: 51.55588 | Y20: -0.07466753 | Z20: TQ336859 | AA20: N16 8EW | AC20: ="http://tfl.gov.uk/tfl/livetravelnews/trafficcams/cctv/" & Table1[[#This Row],[file]] -> http://tfl.gov.uk/tfl/livetravelnews/trafficcams/cctv/0000101417.jpg | AD20: ="insert into webcam select name = '"&Table1[[#This Row],[location]]&"', xcoord = "&Table1[[#This Row],[lng]]&", ycoord = "&Table1[[#This Row],[lat]]&", url = '"&Table1[[#This Row],[Column1]]&"', radiusofvisibility = 100" -> insert into webcam select name = 'A10 North of Walford Rd', xcoord = -0.07466753, ycoord = 51.55588, url = 'http://tfl.gov.uk/tfl/livetravelnews/trafficcams/cctv/0000101417.jpg', radiusofvisibility = 100
A21: TfL Traffic Cameras | B21: 0.1 | C21: 2014-09-24T09:54:17Z | D21: digital@tfl.gov.uk | E21: Transport for London | F21: 1 | G21: 10 | H21: 10 | L21: http://www.tfl.gov.uk/tfl-global/images/roundel.gif | M21: 1411552457 | N21: /tfl/livetravelnews/trafficcams/cctv/ | O21: 1.01418 | P21: TRUE | R21: A10 North of Evering Rd | T21: 0000101418.jpg | U21: 2014-09-24T09:52:10Z | V21: 533934 | W21: 186144 | X21: 51.558285 | Y21: -0.06935808 | Z21: TQ339861 | AA21: N16 7SH | AC21: ="http://tfl.gov.uk/tfl/livetravelnews/trafficcams/cctv/" & Table1[[#This Row],[file]] -> http://tfl.gov.uk/tfl/livetravelnews/trafficcams/cctv/0000101418.jpg | AD21: ="insert into webcam select name = '"&Table1[[#This Row],[location]]&"', xcoord = "&Table1[[#This Row],[lng]]&", ycoord = "&Table1[[#This Row],[lat]]&", url = '"&Table1[[#This Row],[Column1]]&"', radiusofvisibility = 100" -> insert into webcam select name = 'A10 North of Evering Rd', xcoord = -0.06935808, ycoord = 51.558285, url = 'http://tfl.gov.uk/tfl/livetravelnews/trafficcams/cctv/0000101418.jpg', radiusofvisibility = 100
A22: TfL Traffic Cameras | B22: 0.1 | C22: 2014-09-24T09:54:17Z | D22: digital@tfl.gov.uk | E22: Transport for London | F22: 1 | G22: 10 | H22: 10 | L22: http://www.tfl.gov.uk/tfl-global/images/roundel.gif | M22: 1411552457 | N22: /tfl/livetravelnews/trafficcams/cctv/ | O22: 1.01419 | P22: FALSE | R22: A10 North of Tyssen Road | T22: 0000101419.jpg | U22: 1970-01-01T00:00:00Z | V22: 533592 | W22: 186282 | X22: 51.559605 | Y22: -0.0742361 | Z22: TQ336863 | AA22: N16 0DB | AB22: Unavailable due to camera fault | AC22: ="http://tfl.gov.uk/tfl/livetravelnews/trafficcams/cctv/" & Table1[[#This Row],[file]] -> http://tfl.gov.uk/tfl/livetravelnews/trafficcams/cctv/0000101419.jpg | AD22: ="insert into webcam select name = '"&Table1[[#This Row],[location]]&"', xcoord = "&Table1[[#This Row],[lng]]&", ycoord = "&Table1[[#This Row],[lat]]&", url = '"&Table1[[#This Row],[Column1]]&"', radiusofvisibility = 100" -> insert into webcam select name = 'A10 North of Tyssen Road', xcoord = -0.0742361, ycoord = 51.559605, url = 'http://tfl.gov.uk/tfl/livetravelnews/trafficcams/cctv/0000101419.jpg', radiusofvisibility = 100
A23: TfL Traffic Cameras | B23: 0.1 | C23: 2014-09-24T09:54:17Z | D23: digital@tfl.gov.uk | E23: Transport for London | F23: 1 | G23: 10 | H23: 10 | L23: http://www.tfl.gov.uk/tfl-global/images/roundel.gif | M23: 1411552457 | N23: /tfl/livetravelnews/trafficcams/cctv/ | O23: 1.0142 | P23: TRUE | R23: A10 North of Brooke Road | T23: 0000101420.jpg | U23: 2014-09-24T09:52:04Z | V23: 533844 | W23: 186399 | X23: 51.560596 | Y23: -0.07055857 | Z23: TQ338864 | AA23: N16 7LR | AC23: ="http://tfl.gov.uk/tfl/livetravelnews/trafficcams/cctv/" & Table1[[#This Row],[file]] -> http://tfl.gov.uk/tfl/livetravelnews/trafficcams/cctv/0000101420.jpg | AD23: ="insert into webcam select name = '"&Table1[[#This Row],[location]]&"', xcoord = "&Table1[[#This Row],[lng]]&", ycoord = "&Table1[[#This Row],[lat]]&", url = '"&Table1[[#This Row],[Column1]]&"', radiusofvisibility = 100" -> insert into webcam select name = 'A10 North of Brooke Road', xcoord = -0.07055857, ycoord = 51.560596, url = 'http://tfl.gov.uk/tfl/livetravelnews/trafficcams/cctv/0000101420.jpg', radiusofvisibility = 100
A24: TfL Traffic Cameras | B24: 0.1 | C24: 2014-09-24T09:54:17Z | D24: digital@tfl.gov.uk | E24: Transport for London | F24: 1 | G24: 10 | H24: 10 | L24: http://www.tfl.gov.uk/tfl-global/images/roundel.gif | M24: 1411552457 | N24: /tfl/livetravelnews/trafficcams/cctv/ | O24: 1.01421 | P24: FALSE | R24: A10 North of Northwold Rd | T24: 0000101421.jpg | U24: 1970-01-01T00:00:00Z | V24: 533649 | W24: 186725 | X24: 51.563572 | Y24: -0.07324608 | Z24: TQ336867 | AA24: N16 7HF | AB24: In use keeping London moving | AC24: ="http://tfl.gov.uk/tfl/livetravelnews/trafficcams/cctv/" & Table1[[#This Row],[file]] -> http://tfl.gov.uk/tfl/livetravelnews/trafficcams/cctv/0000101421.jpg | AD24: ="insert into webcam select name = '"&Table1[[#This Row],[location]]&"', xcoord = "&Table1[[#This Row],[lng]]&", ycoord = "&Table1[[#This Row],[lat]]&", url = '"&Table1[[#This Row],[Column1]]&"', radiusofvisibility = 100" -> insert into webcam select name = 'A10 North of Northwold Rd', xcoord = -0.07324608, ycoord = 51.563572, url = 'http://tfl.gov.uk/tfl/livetravelnews/trafficcams/cctv/0000101421.jpg', radiusofvisibility = 100
A25: TfL Traffic Cameras | B25: 0.1 | C25: 2014-09-24T09:54:17Z | D25: digital@tfl.gov.uk | E25: Transport for London | F25: 1 | G25: 10 | H25: 10 | L25: http://www.tfl.gov.uk/tfl-global/images/roundel.gif | M25: 1411552457 | N25: /tfl/livetravelnews/trafficcams/cctv/ | O25: 1.01426 | P25: FALSE | R25: A10 High Rd/Forster Rd | T25: 0000101426.jpg | U25: 1970-01-01T00:00:00Z | V25: 533790 | W25: 189879 | X25: 51.591885 | Y25: -0.07001277 | Z25: TQ338899 | AA25: N17 6QB | AB25: In use keeping London moving | AC25: ="http://tfl.gov.uk/tfl/livetravelnews/trafficcams/cctv/" & Table1[[#This Row],[file]] -> http://tfl.gov.uk/tfl/livetravelnews/trafficcams/cctv/0000101426.jpg | AD25: ="insert into webcam select name = '"&Table1[[#This Row],[location]]&"', xcoord = "&Table1[[#This Row],[lng]]&", ycoord = "&Table1[[#This Row],[lat]]&", url = '"&Table1[[#This Row],[Column1]]&"', radiusofvisibility = 100" -> insert into webcam select name = 'A10 High Rd/Forster Rd', xcoord = -0.07001277, ycoord = 51.591885, url = 'http://tfl.gov.uk/tfl/livetravelnews/trafficcams/cctv/0000101426.jpg', radiusofvisibility = 100
A26: TfL Traffic Cameras | B26: 0.1 | C26: 2014-09-24T09:54:17Z | D26: digital@tfl.gov.uk | E26: Transport for London | F26: 1 | G26: 10 | H26: 10 | L26: http://www.tfl.gov.uk/tfl-global/images/roundel.gif | M26: 1411552457 | N26: /tfl/livetravelnews/trafficcams/cctv/ | O26: 1.01427 | P26: FALSE | R26: Bruce Grove | T26: 0000101427.jpg | U26: 1970-01-01T00:00:00Z | V26: 533824 | W26: 190113 | X26: 51.59398 | Y26: -0.06943309 | Z26: TQ338901 | AB26: Unavailable due to camera fault | AC26: ="http://tfl.gov.uk/tfl/livetravelnews/trafficcams/cctv/" & Table1[[#This Row],[file]] -> http://tfl.gov.uk/tfl/livetravelnews/trafficcams/cctv/0000101427.jpg | AD26: ="insert into webcam select name = '"&Table1[[#This Row],[location]]&"', xcoord = "&Table1[[#This Row],[lng]]&", ycoord = "&Table1[[#This Row],[lat]]&", url = '"&Table1[[#This Row],[Column1]]&"', radiusofvisibility = 100" -> insert into webcam select name = 'Bruce Grove', xcoord = -0.06943309, ycoord = 51.59398, url = 'http://tfl.gov.uk/tfl/livetravelnews/trafficcams/cctv/0000101427.jpg', radiusofvisibility = 100
A27: TfL Traffic Cameras | B27: 0.1 | C27: 2014-09-24T09:54:17Z | D27: digital@tfl.gov.uk | E27: Transport for London | F27: 1 | G27: 10 | H27: 10 | L27: http://www.tfl.gov.uk/tfl-global/images/roundel.gif | M27: 1411552457 | N27: /tfl/livetravelnews/trafficcams/cctv/ | O27: 1.01428 | P27: TRUE | R27: A10 Grt Cambridge Rd/Devonshire H Ln | T27: 0000101428.jpg | U27: 2014-09-24T09:52:08Z | V27: 532670 | W27: 191502 | X27: 51.60673 | Y27: -0.08555785 | Z27: TQ327915 | AA27: N17 8LP | AC27: ="http://tfl.gov.uk/tfl/livetravelnews/trafficcams/cctv/" & Table1[[#This Row],[file]] -> http://tfl.gov.uk/tfl/livetravelnews/trafficcams/cctv/0000101428.jpg | AD27: ="insert into webcam select name = '"&Table1[[#This Row],[location]]&"', xcoord = "&Table1[[#This Row],[lng]]&", ycoord = "&Table1[[#This Row],[lat]]&", url = '"&Table1[[#This Row],[Column1]]&"', radiusofvisibility = 100" -> insert into webcam select name = 'A10 Grt Cambridge Rd/Devonshire H Ln', xcoord = -0.08555785, ycoord = 51.60673, url = 'http://tfl.gov.uk/tfl/livetravelnews/trafficcams/cctv/0000101428.jpg', radiusofvisibility = 100
A28: TfL Traffic Cameras | B28: 0.1 | C28: 2014-09-24T09:54:17Z | D28: digital@tfl.gov.uk | E28: Transport for London | F28: 1 | G28: 10 | H28: 10 | L28: http://www.tfl.gov.uk/tfl-global/images/roundel.gif | M28: 1411552457 | N28: /tfl/livetravelnews/trafficcams/cctv/ | O28: 1.01429 | P28: TRUE | R28: Grt Cambridge Rd/Bullsmore Ln | T28: 0000101429.jpg | U28: 2014-09-24T09:52:36Z | V28: 534822 | W28: 199698 | X28: 51.67987 | Y28: -0.051345743 | Z28: TQ348997 | AA28: EN1 4SG | AC28: ="http://tfl.gov.uk/tfl/livetravelnews/trafficcams/cctv/" & Table1[[#This Row],[file]] -> http://tfl.gov.uk/tfl/livetravelnews/trafficcams/cctv/0000101429.jpg | AD28: ="insert into webcam select name = '"&Table1[[#This Row],[location]]&"', xcoord = "&Table1[[#This Row],[lng]]&", ycoord = "&Table1[[#This Row],[lat]]&", url = '"&Table1[[#This Row],[Column1]]&"', radiusofvisibility = 100" -> insert into webcam select name = 'Grt Cambridge Rd/Bullsmore Ln', xcoord = -0.051345743, ycoord = 51.67987, url = 'http://tfl.gov.uk/tfl/livetravelnews/trafficcams/cctv/0000101429.jpg', radiusofvisibility = 100
A29: TfL Traffic Cameras | B29: 0.1 | C29: 2014-09-24T09:54:17Z | D29: digital@tfl.gov.uk | E29: Transport for London | F29: 1 | G29: 10 | H29: 10 | L29: http://www.tfl.gov.uk/tfl-global/images/roundel.gif | M29: 1411552457 | N29: /tfl/livetravelnews/trafficcams/cctv/ | O29: 1.0143 | P29: TRUE | R29: Stamford Hill/Amhurst Pk | T29: 0000101430.jpg | U29: 2014-09-24T09:53:06Z | V29: 533660 | W29: 187801 | X29: 51.573242 | Y29: -0.07267859 | Z29: TQ337878 | AA29: N16 5RY | AC29: ="http://tfl.gov.uk/tfl/livetravelnews/trafficcams/cctv/" & Table1[[#This Row],[file]] -> http://tfl.gov.uk/tfl/livetravelnews/trafficcams/cctv/0000101430.jpg | AD29: ="insert into webcam select name = '"&Table1[[#This Row],[location]]&"', xcoord = "&Table1[[#This Row],[lng]]&", ycoord = "&Table1[[#This Row],[lat]]&", url = '"&Table1[[#This Row],[Column1]]&"', radiusofvisibility = 100" -> insert into webcam select name = 'Stamford Hill/Amhurst Pk', xcoord = -0.07267859, ycoord = 51.573242, url = 'http://tfl.gov.uk/tfl/livetravelnews/trafficcams/cctv/0000101430.jpg', radiusofvisibility = 100
A30: TfL Traffic Cameras | B30: 0.1 | C30: 2014-09-24T09:54:17Z | D30: digital@tfl.gov.uk | E30: Transport for London | F30: 1 | G30: 10 | H30: 10 | L30: http://www.tfl.gov.uk/tfl-global/images/roundel.gif | M30: 1411552457 | N30: /tfl/livetravelnews/trafficcams/cctv/ | O30: 1.01431 | P30: FALSE | R30: Stamford Hill/Manor Rd | T30: 0000101431.jpg | U30: 1970-01-01T00:00:00Z | V30: 533659 | W30: 186904 | X30: 51.56518 | Y30: -0.07303389 | Z30: TQ337869 | AA30: N16 6YA | AB30: In use keeping London moving | AC30: ="http://tfl.gov.uk/tfl/livetravelnews/trafficcams/cctv/" & Table1[[#This Row],[file]] -> http://tfl.gov.uk/tfl/livetravelnews/trafficcams/cctv/0000101431.jpg | AD30: ="insert into webcam select name = '"&Table1[[#This Row],[location]]&"', xcoord = "&Table1[[#This Row],[lng]]&", ycoord = "&Table1[[#This Row],[lat]]&", url = '"&Table1[[#This Row],[Column1]]&"', radiusofvisibility = 100" -> insert into webcam select name = 'Stamford Hill/Manor Rd', xcoord = -0.07303389, ycoord = 51.56518, url = 'http://tfl.gov.uk/tfl/livetravelnews/trafficcams/cctv/0000101431.jpg', radiusofvisibility = 100
A31: TfL Traffic Cameras | B31: 0.1 | C31: 2014-09-24T09:54:17Z | D31: digital@tfl.gov.uk | E31: Transport for London | F31: 1 | G31: 10 | H31: 10 | L31: http://www.tfl.gov.uk/tfl-global/images/roundel.gif | M31: 1411552457 | N31: /tfl/livetravelnews/trafficcams/cctv/ | O31: 1.01432 | P31: TRUE | R31: Lr Clapton Rd/Thislewaite Rd | T31: 0000101432.jpg | U31: 2014-09-24T09:53:22Z | V31: 534868 | W31: 186025 | X31: 51.55699 | Y31: -0.05593888 | Z31: TQ349860 | AA31: E5 8EY | AC31: ="http://tfl.gov.uk/tfl/livetravelnews/trafficcams/cctv/" & Table1[[#This Row],[file]] -> http://tfl.gov.uk/tfl/livetravelnews/trafficcams/cctv/0000101432.jpg | AD31: ="insert into webcam select name = '"&Table1[[#This Row],[location]]&"', xcoord = "&Table1[[#This Row],[lng]]&", ycoord = "&Table1[[#This Row],[lat]]&", url = '"&Table1[[#This Row],[Column1]]&"', radiusofvisibility = 100" -> insert into webcam select name = 'Lr Clapton Rd/Thislewaite Rd', xcoord = -0.05593888, ycoord = 51.55699, url = 'http://tfl.gov.uk/tfl/livetravelnews/trafficcams/cctv/0000101432.jpg', radiusofvisibility = 100
A32: TfL Traffic Cameras | B32: 0.1 | C32: 2014-09-24T09:54:17Z | D32: digital@tfl.gov.uk | E32: Transport for London | F32: 1 | G32: 10 | H32: 10 | L32: http://www.tfl.gov.uk/tfl-global/images/roundel.gif | M32: 1411552457 | N32: /tfl/livetravelnews/trafficcams/cctv/ | O32: 1.01433 | P32: TRUE | R32: Clapton Common/Lewstone Place | T32: 0000101433.jpg | U32: 2014-09-24T09:53:20Z | V32: 533795 | W32: 187768 | X32: 51.57291 | Y32: -0.0707443 | Z32: TQ338878 | AA32: E5 9AG | AC32: ="http://tfl.gov.uk/tfl/livetravelnews/trafficcams/cctv/" & Table1[[#This Row],[file]] -> http://tfl.gov.uk/tfl/livetravelnews/trafficcams/cctv/0000101433.jpg | AD32: ="insert into webcam select name = '"&Table1[[#This Row],[location]]&"', xcoord = "&Table1[[#This Row],[lng]]&", ycoord = "&Table1[[#This Row],[lat]]&", url = '"&Table1[[#This Row],[Column1]]&"', radiusofvisibility = 100" -> insert into webcam select name = 'Clapton Common/Lewstone Place', xcoord = -0.0707443, ycoord = 51.57291, url = 'http://tfl.gov.uk/tfl/livetravelnews/trafficcams/cctv/0000101433.jpg', radiusofvisibility = 100
A33: TfL Traffic Cameras | B33: 0.1 | C33: 2014-09-24T09:54:17Z | D33: digital@tfl.gov.uk | E33: Transport for London | F33: 1 | G33: 10 | H33: 10 | L33: http://www.tfl.gov.uk/tfl-global/images/roundel.gif | M33: 1411552457 | N33: /tfl/livetravelnews/trafficcams/cctv/ | O33: 1.01436 | P33: FALSE | R33: Bowes Rd/Brownlow Rd | T33: 0000101436.jpg | U33: 1970-01-01T00:00:00Z | V33: 530188 | W33: 192106 | X33: 51.61274 | Y33: -0.12115418 | Z33: TQ302921 | AA33: N13 4SE | AB33: In use keeping London moving | AC33: ="http://tfl.gov.uk/tfl/livetravelnews/trafficcams/cctv/" & Table1[[#This Row],[file]] -> http://tfl.gov.uk/tfl/livetravelnews/trafficcams/cctv/0000101436.jpg | AD33: ="insert into webcam select name = '"&Table1[[#This Row],[location]]&"', xcoord = "&Table1[[#This Row],[lng]]&", ycoord = "&Table1[[#This Row],[lat]]&", url = '"&Table1[[#This Row],[Column1]]&"', radiusofvisibility = 100" -> insert into webcam select name = 'Bowes Rd/Brownlow Rd', xcoord = -0.12115418, ycoord = 51.61274, url = 'http://tfl.gov.uk/tfl/livetravelnews/trafficcams/cctv/0000101436.jpg', radiusofvisibility = 100
A34: TfL Traffic Cameras | B34: 0.1 | C34: 2014-09-24T09:54:17Z | D34: digital@tfl.gov.uk | E34: Transport for London | F34: 1 | G34: 10 | H34: 10 | L34: http://www.tfl.gov.uk/tfl-global/images/roundel.gif | M34: 1411552457 | N34: /tfl/livetravelnews/trafficcams/cctv/ | O34: 1.01437 | P34: TRUE | R34: Grt Cambridge Rd/A406 NCR R&#039;about | T34: 0000101437.jpg | U34: 2014-09-24T09:52:03Z | V34: 532568 | W34: 192637 | X34: 51.616955 | Y34: -0.08660104 | Z34: TQ326926 | AA34: N13 5DD | AC34: ="http://tfl.gov.uk/tfl/livetravelnews/trafficcams/cctv/" & Table1[[#This Row],[file]] -> http://tfl.gov.uk/tfl/livetravelnews/trafficcams/cctv/0000101437.jpg | AD34: ="insert into webcam select name = '"&Table1[[#This Row],[location]]&"', xcoord = "&Table1[[#This Row],[lng]]&", ycoord = "&Table1[[#This Row],[lat]]&", url = '"&Table1[[#This Row],[Column1]]&"', radiusofvisibility = 100" -> insert into webcam select name = 'Grt Cambridge Rd/A406 NCR R&#039;about', xcoord = -0.08660104, ycoord = 51.616955, url = 'http://tfl.gov.uk/tfl/livetravelnews/trafficcams/cctv/0000101437.jpg', radiusofvisibility = 100
A35: TfL Traffic Cameras | B35: 0.1 | C35: 2014-09-24T09:54:17Z | D35: digital@tfl.gov.uk | E35: Transport for London | F35: 1 | G35: 10 | H35: 10 | L35: http://www.tfl.gov.uk/tfl-global/images/roundel.gif | M35: 1411552457 | N35: /tfl/livetravelnews/trafficcams/cctv/ | O35: 1.01438 | P35: TRUE | R35: Stoke Newington Rd/Evering Rd | T35: 0000101438.jpg | U35: 2014-09-24T09:51:59Z | V35: 533570 | W35: 186003 | X35: 51.557106 | Y35: -0.07465916 | Z35: TQ336860 | AA35: N16 8DT | AC35: ="http://tfl.gov.uk/tfl/livetravelnews/trafficcams/cctv/" & Table1[[#This Row],[file]] -> http://tfl.gov.uk/tfl/livetravelnews/trafficcams/cctv/0000101438.jpg | AD35: ="insert into webcam select name = '"&Table1[[#This Row],[location]]&"', xcoord = "&Table1[[#This Row],[lng]]&", ycoord = "&Table1[[#This Row],[lat]]&", url = '"&Table1[[#This Row],[Column1]]&"', radiusofvisibility = 100" -> insert into webcam select name = 'Stoke Newington Rd/Evering Rd', xcoord = -0.07465916, ycoord = 51.557106, url = 'http://tfl.gov.uk/tfl/livetravelnews/trafficcams/cctv/0000101438.jpg', radiusofvisibility = 100
A36: TfL Traffic Cameras | B36: 0.1 | C36: 2014-09-24T09:54:17Z | D36: digital@tfl.gov.uk | E36: Transport for London | F36: 1 | G36: 10 | H36: 10 | L36: http://www.tfl.gov.uk/tfl-global/images/roundel.gif | M36: 1411552457 | N36: /tfl/livetravelnews/trafficcams/cctv/ | O36: 1.01439 | P36: TRUE | R36: Shoreditch High St/Batemans Row | T36: 0000101439.jpg | U36: 2014-09-24T09:53:22Z | V36: 533479 | W36: 182451 | X36: 51.525208 | Y36: -0.07731687 | Z36: TQ335825 | AA36: E1 6JQ | AC36: ="http://tfl.gov.uk/tfl/livetravelnews/trafficcams/cctv/" & Table1[[#This Row],[file]] -> http://tfl.gov.uk/tfl/livetravelnews/trafficcams/cctv/0000101439.jpg | AD36: ="insert into webcam select name = '"&Table1[[#This Row],[location]]&"', xcoord = "&Table1[[#This Row],[lng]]&", ycoord = "&Table1[[#This Row],[lat]]&", url = '"&Table1[[#This Row],[Column1]]&"', radiusofvisibility = 100" -> insert into webcam select name = 'Shoreditch High St/Batemans Row', xcoord = -0.07731687, ycoord = 51.525208, url = 'http://tfl.gov.uk/tfl/livetravelnews/trafficcams/cctv/0000101439.jpg', radiusofvisibility = 100
A37: TfL Traffic Cameras | B37: 0.1 | C37: 2014-09-24T09:54:17Z | D37: digital@tfl.gov.uk | E37: Transport for London | F37: 1 | G37: 10 | H37: 10 | L37: http://www.tfl.gov.uk/tfl-global/images/roundel.gif | M37: 1411552457 | N37: /tfl/livetravelnews/trafficcams/cctv/ | O37: 1.0144 | P37: TRUE | R37: Bruce Grove/Woodside Gardens | T37: 0000101440.jpg | U37: 2014-09-24T09:53:16Z | V37: 533712 | W37: 190245 | X37: 51.595192 | Y37: -0.070998736 | Z37: TQ337902 | AA37: N17 6UR | AC37: ="http://tfl.gov.uk/tfl/livetravelnews/trafficcams/cctv/" & Table1[[#This Row],[file]] -> http://tfl.gov.uk/tfl/livetravelnews/trafficcams/cctv/0000101440.jpg | AD37: ="insert into webcam select name = '"&Table1[[#This Row],[location]]&"', xcoord = "&Table1[[#This Row],[lng]]&", ycoord = "&Table1[[#This Row],[lat]]&", url = '"&Table1[[#This Row],[Column1]]&"', radiusofvisibility = 100" -> insert into webcam select name = 'Bruce Grove/Woodside Gardens', xcoord = -0.070998736, ycoord = 51.595192, url = 'http://tfl.gov.uk/tfl/livetravelnews/trafficcams/cctv/0000101440.jpg', radiusofvisibility = 100
A38: TfL Traffic Cameras | B38: 0.1 | C38: 2014-09-24T09:54:17Z | D38: digital@tfl.gov.uk | E38: Transport for London | F38: 1 | G38: 10 | H38: 10 | L38: http://www.tfl.gov.uk/tfl-global/images/roundel.gif | M38: 1411552457 | N38: /tfl/livetravelnews/trafficcams/cctv/ | O38: 1.01441 | P38: TRUE | R38: Stamford Hill/Dunsmure Road | T38: 0000101441.jpg | U38: 2014-09-24T09:51:59Z | V38: 533649 | W38: 187463 | X38: 51.570206 | Y38: -0.07296568 | Z38: TQ336875 | AA38: N16 5TZ | AC38: ="http://tfl.gov.uk/tfl/livetravelnews/trafficcams/cctv/" & Table1[[#This Row],[file]] -> http://tfl.gov.uk/tfl/livetravelnews/trafficcams/cctv/0000101441.jpg | AD38: ="insert into webcam select name = '"&Table1[[#This Row],[location]]&"', xcoord = "&Table1[[#This Row],[lng]]&", ycoord = "&Table1[[#This Row],[lat]]&", url = '"&Table1[[#This Row],[Column1]]&"', radiusofvisibility = 100" -> insert into webcam select name = 'Stamford Hill/Dunsmure Road', xcoord = -0.07296568, ycoord = 51.570206, url = 'http://tfl.gov.uk/tfl/livetravelnews/trafficcams/cctv/0000101441.jpg', radiusofvisibility = 100
A39: TfL Traffic Cameras | B39: 0.1 | C39: 2014-09-24T09:54:17Z | D39: digital@tfl.gov.uk | E39: Transport for London | F39: 1 | G39: 10 | H39: 10 | L39: http://www.tfl.gov.uk/tfl-global/images/roundel.gif | M39: 1411552457 | N39: /tfl/livetravelnews/trafficcams/cctv/ | O39: 1.01442 | P39: TRUE | R39: Stamford Hill/Egerton Rd | T39: 0000101442.jpg | U39: 2014-09-24T09:52:36Z | V39: 533689 | W39: 187922 | X39: 51.57432 | Y39: -0.07221437 | Z39: TQ337879 | AA39: N16 6TW | AC39: ="http://tfl.gov.uk/tfl/livetravelnews/trafficcams/cctv/" & Table1[[#This Row],[file]] -> http://tfl.gov.uk/tfl/livetravelnews/trafficcams/cctv/0000101442.jpg | AD39: ="insert into webcam select name = '"&Table1[[#This Row],[location]]&"', xcoord = "&Table1[[#This Row],[lng]]&", ycoord = "&Table1[[#This Row],[lat]]&", url = '"&Table1[[#This Row],[Column1]]&"', radiusofvisibility = 100" -> insert into webcam select name = 'Stamford Hill/Egerton Rd', xcoord = -0.07221437, ycoord = 51.57432, url = 'http://tfl.gov.uk/tfl/livetravelnews/trafficcams/cctv/0000101442.jpg', radiusofvisibility = 100
A40: TfL Traffic Cameras | B40: 0.1 | C40: 2014-09-24T09:54:17Z | D40: digital@tfl.gov.uk | E40: Transport for London | F40: 1 | G40: 10 | H40: 10 | L40: http://www.tfl.gov.uk/tfl-global/images/roundel.gif | M40: 1411552457 | N40: /tfl/livetravelnews/trafficcams/cctv/ | O40: 1.01445 | P40: TRUE | R40: A10 Grt Cambridge Rd/A110 S&#039; bury Rd | T40: 0000101445.jpg | U40: 2014-09-24T09:52:36Z | V40: 534286 | W40: 196318 | X40: 51.649628 | Y40: -0.060391203 | Z40: TQ343963 | AA40: EN1 1RQ | AC40: ="http://tfl.gov.uk/tfl/livetravelnews/trafficcams/cctv/" & Table1[[#This Row],[file]] -> http://tfl.gov.uk/tfl/livetravelnews/trafficcams/cctv/0000101445.jpg | AD40: ="insert into webcam select name = '"&Table1[[#This Row],[location]]&"', xcoord = "&Table1[[#This Row],[lng]]&", ycoord = "&Table1[[#This Row],[lat]]&", url = '"&Table1[[#This Row],[Column1]]&"', radiusofvisibility = 100" -> insert into webcam select name = 'A10 Grt Cambridge Rd/A110 S&#039; bury Rd', xcoord = -0.060391203, ycoord = 51.649628, url = 'http://tfl.gov.uk/tfl/livetravelnews/trafficcams/cctv/0000101445.jpg', radiusofvisibility = 100
...

Sheet Sydney
A1: |__features | B1: |__geometry__coordinates001 | C1: |__geometry__coordinates002 | D1: |__geometry__type | E1: |__id | F1: |__properties__direction | G1: |__properties__href | H1: |__properties__region | I1: |__properties__title | J1: |__properties__view | K1: |__type | L1: type | M1: |__copyright | N1: |__licence
B2: 151.10533 | C2: -34.02977 | D2: Point | E2: d2e386 | F2: W | G2: http://www.rms.nsw.gov.au/trafficreports/cameras/camera_images/5ways.jpg | H2: SYD_SOUTH | I2: 5 Ways (Miranda) | J2: 5 ways at The Boulevarde looking west towards Sutherland. | K2: Feature | L2: FeatureCollection | O2: ="insert into webcam select name = '"&Sydney!I2&"', xcoord = "&Sydney!B2&", ycoord = "&Sydney!C2&", url = '"&Sydney!G2&"', radiusofvisibility = 500" -> insert into webcam select name = '5 Ways (Miranda)', xcoord = 151.10533, ycoord = -34.0297699999999, url = 'http://www.rms.nsw.gov.au/trafficreports/cameras/camera_images/5ways.jpg', radiusofvisibility = 500
B3: 151.23122 | C3: -33.90641 | D3: Point | E3: d2e5699 | F3: N-W | G3: http://www.rms.nsw.gov.au/trafficreports/cameras/camera_images/alisonrd_randwick.jpg | H3: SYD_MET | I3: Alison Road (Randwick) | J3: Alison Road at Darley Street looking north-west towards Anzac Parade. | K3: Feature | O3: ="insert into webcam select name = '"&Sydney!I3&"', xcoord = "&Sydney!B3&", ycoord = "&Sydney!C3&", url = '"&Sydney!G3&"', radiusofvisibility = 500" -> insert into webcam select name = 'Alison Road (Randwick)', xcoord = 151.23122, ycoord = -33.90641, url = 'http://www.rms.nsw.gov.au/trafficreports/cameras/camera_images/alisonrd_randwick.jpg', radiusofvisibility = 500
B4: 151.18022 | C4: -33.86789 | D4: Point | E4: d2e649 | F4: E | G4: http://www.rms.nsw.gov.au/trafficreports/cameras/camera_images/anzacbr.jpg | H4: SYD_MET | I4: Anzac Bridge | J4: Intersection of Victoria Road and Anzac Bridge looking east towards the Sydney CBD. | K4: Feature | O4: ="insert into webcam select name = '"&Sydney!I4&"', xcoord = "&Sydney!B4&", ycoord = "&Sydney!C4&", url = '"&Sydney!G4&"', radiusofvisibility = 500" -> insert into webcam select name = 'Anzac Bridge', xcoord = 151.180219999999, ycoord = -33.86789, url = 'http://www.rms.nsw.gov.au/trafficreports/cameras/camera_images/anzacbr.jpg', radiusofvisibility = 500
B5: 151.22151 | C5: -33.89534 | D5: Point | E5: d2e4913 | F5: S | G5: http://www.rms.nsw.gov.au/trafficreports/cameras/camera_images/anzacpde.jpg | H5: SYD_MET | I5: Anzac Parade (Moore Park) | J5: Corner of Anzac Parade and Cleveland Street looking south towards Randwick. | K5: Feature | O5: ="insert into webcam select name = '"&Sydney!I5&"', xcoord = "&Sydney!B5&", ycoord = "&Sydney!C5&", url = '"&Sydney!G5&"', radiusofvisibility = 500" -> insert into webcam select name = 'Anzac Parade (Moore Park)', xcoord = 151.221509999999, ycoord = -33.8953399999999, url = 'http://www.rms.nsw.gov.au/trafficreports/cameras/camera_images/anzacpde.jpg', radiusofvisibility = 500
B6: 151.00533 | C6: -33.80866 | D6: Point | E6: d2e5786 | F6: N | G6: http://www.rms.nsw.gov.au/trafficreports/cameras/camera_images/churchst_parra.jpg | H6: SYD_WEST | I6: Church Street (Parramatta) | J6: Corner of Church Street and Victoria Road looking north towards Northmead. | K6: Feature | O6: ="insert into webcam select name = '"&Sydney!I6&"', xcoord = "&Sydney!B6&", ycoord = "&Sydney!C6&", url = '"&Sydney!G6&"', radiusofvisibility = 500" -> insert into webcam select name = 'Church Street (Parramatta)', xcoord = 151.005329999999, ycoord = -33.80866, url = 'http://www.rms.nsw.gov.au/trafficreports/cameras/camera_images/churchst_parra.jpg', radiusofvisibility = 500
B7: 151.17183 | C7: -33.87175 | D7: Point | E7: d2e3350 | F7: E | G7: http://www.rms.nsw.gov.au/trafficreports/cameras/camera_images/citywestlink.jpg | H7: SYD_MET | I7: City West Link | J7: City West Link at Lilyfield looking east towards Victoria Road intersection. | K7: Feature | O7: ="insert into webcam select name = '"&Sydney!I7&"', xcoord = "&Sydney!B7&", ycoord = "&Sydney!C7&", url = '"&Sydney!G7&"', radiusofvisibility = 500" -> insert into webcam select name = 'City West Link', xcoord = 151.17183, ycoord = -33.8717499999999, url = 'http://www.rms.nsw.gov.au/trafficreports/cameras/camera_images/citywestlink.jpg', radiusofvisibility = 500
B8: 151.05237 | C8: -33.77967 | D8: Point | E8: d2e822 | F8: N | G8: http://www.rms.nsw.gov.au/trafficreports/cameras/camera_images/cumberlandhwy_carlingford.jpg | H8: SYD_NORTH | I8: Cumberland Highway (Carlingford) | J8: Cumberland Highway at Marsden Road looking north towards Beecroft. | K8: Feature | O8: ="insert into webcam select name = '"&Sydney!I8&"', xcoord = "&Sydney!B8&", ycoord = "&Sydney!C8&", url = '"&Sydney!G8&"', radiusofvisibility = 500" -> insert into webcam select name = 'Cumberland Highway (Carlingford)', xcoord = 151.05237, ycoord = -33.77967, url = 'http://www.rms.nsw.gov.au/trafficreports/cameras/camera_images/cumberlandhwy_carlingford.jpg', radiusofvisibility = 500
B9: 150.96039 | C9: -33.83031 | D9: Point | E9: d2e735 | F9: N | G9: http://www.rms.nsw.gov.au/trafficreports/cameras/camera_images/cumberlandhwy_merrylands.jpg | H9: SYD_WEST | I9: Cumberland Highway (Merrylands) | J9: Cumberland Highway at Merrylands Road looking north towards the M4 Western Motorway. | K9: Feature | O9: ="insert into webcam select name = '"&Sydney!I9&"', xcoord = "&Sydney!B9&", ycoord = "&Sydney!C9&", url = '"&Sydney!G9&"', radiusofvisibility = 500" -> insert into webcam select name = 'Cumberland Highway (Merrylands)', xcoord = 150.960389999999, ycoord = -33.8303099999999, url = 'http://www.rms.nsw.gov.au/trafficreports/cameras/camera_images/cumberlandhwy_merrylands.jpg', radiusofvisibility = 500
B10: 151.21303 | C10: -33.90964 | D10: Point | E10: d2e5175 | F10: N | G10: http://www.rms.nsw.gov.au/trafficreports/cameras/camera_images/easterndist.jpg | H10: SYD_MET | I10: Eastern Distributor | J10: Southern end of the Eastern Distributor tunnel near the Link Road on-ramp looking north towards Sydney. | K10: Feature | O10: ="insert into webcam select name = '"&Sydney!I10&"', xcoord = "&Sydney!B10&", ycoord = "&Sydney!C10&", url = '"&Sydney!G10&"', radiusofvisibility = 500" -> insert into webcam select name = 'Eastern Distributor', xcoord = 151.21303, ycoord = -33.90964, url = 'http://www.rms.nsw.gov.au/trafficreports/cameras/camera_images/easterndist.jpg', radiusofvisibility = 500
B11: 151.29416 | C11: -33.4184 | D11: Point | E11: d2e2912 | F11: S | G11: http://www.rms.nsw.gov.au/trafficreports/cameras/camera_images/f3_kariong.jpg | H11: REG_NORTH | I11: M1 Pacific Motorway (Kariong) | J11: M1 Pacific Motorway at the Kariong on ramp looking south towards Sydney. | K11: Feature | O11: ="insert into webcam select name = '"&Sydney!I11&"', xcoord = "&Sydney!B11&", ycoord = "&Sydney!C11&", url = '"&Sydney!G11&"', radiusofvisibility = 500" -> insert into webcam select name = 'M1 Pacific Motorway (Kariong)', xcoord = 151.29416, ycoord = -33.4183999999999, url = 'http://www.rms.nsw.gov.au/trafficreports/cameras/camera_images/f3_kariong.jpg', radiusofvisibility = 500
B12: 151.20082 | C12: -33.53074 | D12: Point | E12: d2e909 | F12: S | G12: http://www.rms.nsw.gov.au/trafficreports/cameras/camera_images/f3_mooney.jpg | H12: REG_NORTH | I12: M1 Pacific Motorway (Hawkesbury River) | J12: M1 Pacific Motorway crossing the Hawkesbury River Bridge looking south towards Sydney. | K12: Feature | O12: ="insert into webcam select name = '"&Sydney!I12&"', xcoord = "&Sydney!B12&", ycoord = "&Sydney!C12&", url = '"&Sydney!G12&"', radiusofvisibility = 500" -> insert into webcam select name = 'M1 Pacific Motorway (Hawkesbury River)', xcoord = 151.200819999999, ycoord = -33.53074, url = 'http://www.rms.nsw.gov.au/trafficreports/cameras/camera_images/f3_mooney.jpg', radiusofvisibility = 500
B13: 151.20595 | C13: -33.45451 | D13: Point | E13: d2e5351 | F13: N | G13: http://www.rms.nsw.gov.au/trafficreports/cameras/camera_images/f3_mountwhite.jpg | H13: REG_NORTH | I13: M1 Pacific Motorway (Mount White) | J13: M1 Pacific Motorway at the Mount White heavy vehicle checking station looking north towards Calga. | K13: Feature | O13: ="insert into webcam select name = '"&Sydney!I13&"', xcoord = "&Sydney!B13&", ycoord = "&Sydney!C13&", url = '"&Sydney!G13&"', radiusofvisibility = 500" -> insert into webcam select name = 'M1 Pacific Motorway (Mount White)', xcoord = 151.20595, ycoord = -33.4545099999999, url = 'http://www.rms.nsw.gov.au/trafficreports/cameras/camera_images/f3_mountwhite.jpg', radiusofvisibility = 500
B14: 151.36906 | C14: -33.34475 | D14: Point | E14: d2e3437 | F14: N | G14: http://www.rms.nsw.gov.au/trafficreports/cameras/camera_images/f3_ourimbah.jpg | H14: REG_NORTH | I14: M1 Pacific Motorway (Ourimbah) | J14: M1 Pacific Motorway at Ourimbah on ramp looking north towards Wyong. | K14: Feature | O14: ="insert into webcam select name = '"&Sydney!I14&"', xcoord = "&Sydney!B14&", ycoord = "&Sydney!C14&", url = '"&Sydney!G14&"', radiusofvisibility = 500" -> insert into webcam select name = 'M1 Pacific Motorway (Ourimbah)', xcoord = 151.369059999999, ycoord = -33.3447499999999, url = 'http://www.rms.nsw.gov.au/trafficreports/cameras/camera_images/f3_ourimbah.jpg', radiusofvisibility = 500
... B88: 150.8926 | C88: -34.412822 | D88: Point | E88: d2e6019 | F88: N | G88: http://www.rms.nsw.gov.au/trafficreports/cameras/camera_images/princeshwy_wollongong.jpg | H88: REG_SOUTH | I88: Princes Highway (Wollongong) | J88: Princes Highway near Bourke Street looking north towards Bulli. | K88: Feature | O88: ="insert into webcam select name = '"&Sydney!I88&"', xcoord = "&Sydney!B88&", ycoord = "&Sydney!C88&", url = '"&Sydney!G88&"', radiusofvisibility = 500" -> insert into webcam select name = 'Princes Highway (Wollongong)', xcoord = 150.892599999999, ycoord = -34.4128219999999, url = 'http://www.rms.nsw.gov.au/trafficreports/cameras/camera_images/princeshwy_wollongong.jpg', radiusofvisibility = 500

Sheet NZ
A1: ns1:congestion | B1: ns1:direction | C1: ns1:endLat | D1: ns1:endLon | E1: ns1:order | F1: ns1:startLat | G1: ns1:startLon | H1: ns1:id | I1: ns1:inOut | J1: ns1:name | K1: ns1:description | L1: ns1:direction2 | M1: ns1:group | N1: ns1:id3 | O1: ns1:imageUrl | P1: ns1:lat | Q1: ns1:lon | R1: ns1:name4 | S1: ns1:offline | T1: ns1:region | U1: ns1:thumbUrl | V1: ns1:underMaintenance | W1: ns1:viewUrl | X1: Column1 | Y1: Column2
A2: Free Flow | B2: Westbound | C2: -36.868872 | D2: 174.72587 | E2: 2 | F2: -36.8623 | G2: 174.75452 | H2: 24 | J2: Newton Rd - St Lukes Rd | X2: ="insert into webcam select name = '"&R11&"', xcoord = "&Q10&", ycoord = "&P9&", url = '"&O8&"', radiusofvisibility = 500 where (select count(*) from webcam where url = '"&O8&"') = 0" -> insert into webcam select name = 'SH16 1 Bond St', xcoord = 174.746, ycoord = -36.869, url = 'http://www.trafficnz.info/camera/130.jpg', radiusofvisibility = 500 where (select count(*) from webcam where url = 'http://www.trafficnz.info/camera/130.jpg') = 0 | Y2: =IF(LEN(K4) > 0, Table13[[#This Row],[Column1]], "") -> insert into webcam select name = 'SH16 1 Bond St', xcoord = 174.746, ycoord = -36.869, url = 'http://www.trafficnz.info/camera/130.jpg', radiusofvisibility = 500 where (select count(*) from webcam where url = 'http://www.trafficnz.info/camera/130.jpg') = 0
A3: Free Flow | B3: Eastbound | C3: -36.861933 | D3: 174.75405 | E3: 6 | F3: -36.868742 | G3: 174.7259 | H3: 23 | J3: St Lukes Rd - Newton Rd | X3: ="insert into webcam select name = '"&R12&"', xcoord = "&Q11&", ycoord = "&P10&", url = '"&O9&"', radiusofvisibility = 500 where (select count(*) from webcam where url = '"&O9&"') = 0" -> insert into webcam select name = '', xcoord = , ycoord = , url = '', radiusofvisibility = 500 where (select count(*) from webcam where url = '') = 0 | Y3: =IF(LEN(K5) > 0, Table13[[#This Row],[Column1]], "")
K4: Bond St looking East | X4: ="insert into webcam select name = '"&R13&"', xcoord = "&Q12&", ycoord = "&P11&", url = '"&O10&"', radiusofvisibility = 500 where (select count(*) from webcam where url = '"&O10&"') = 0" -> insert into webcam select name = '', xcoord = , ycoord = , url = '', radiusofvisibility = 500 where (select count(*) from webcam where url = '') = 0 | Y4: =IF(LEN(K6) > 0, Table13[[#This Row],[Column1]], "")
L5: Eastbound | X5: ="insert into webcam select name = '"&R14&"', xcoord = "&Q13&", ycoord = "&P12&", url = '"&O11&"', radiusofvisibility = 500 where (select count(*) from webcam where url = '"&O11&"') = 0" -> insert into webcam select name = '', xcoord = , ycoord = , url = '', radiusofvisibility = 500 where (select count(*) from webcam where url = '') = 0 | Y5: =IF(LEN(K7) > 0, Table13[[#This Row],[Column1]], "")
M6: SH16-North-Western | X6: ="insert into webcam select name = '"&R15&"', xcoord = "&Q14&", ycoord = "&P13&", url = '"&O12&"', radiusofvisibility = 500 where (select count(*) from webcam where url = '"&O12&"') = 0" -> insert into webcam select name = '', xcoord = , ycoord = , url = '', radiusofvisibility = 500 where (select count(*) from webcam where url = '') = 0 | Y6: =IF(LEN(K8) > 0, Table13[[#This Row],[Column1]], "")
N7: 130 | X7: ="insert into webcam select name = '"&R16&"', xcoord = "&Q15&", ycoord = "&P14&", url = '"&O13&"', radiusofvisibility = 500 where (select count(*) from webcam where url = '"&O13&"') = 0" -> insert into webcam select name = '', xcoord = , ycoord = , url = '', radiusofvisibility = 500 where (select count(*) from webcam where url = '') = 0 | Y7: =IF(LEN(K9) > 0, Table13[[#This Row],[Column1]], "")
O8: http://www.trafficnz.info/camera/130.jpg | X8: ="insert into webcam select name = '"&R17&"', xcoord = "&Q16&", ycoord = "&P15&", url = '"&O14&"', radiusofvisibility = 500 where (select count(*) from webcam where url = '"&O14&"') = 0" -> insert into webcam select name = '', xcoord = , ycoord = , url = '', radiusofvisibility = 500 where (select count(*) from webcam where url = '') = 0 | Y8: =IF(LEN(K10) > 0, Table13[[#This Row],[Column1]], "")
P9: -36.869 | X9: ="insert into webcam select name = '"&R18&"', xcoord = "&Q17&", ycoord = "&P16&", url = '"&O15&"', radiusofvisibility = 500 where (select count(*) from webcam where url = '"&O15&"') = 0" -> insert into webcam select name = '', xcoord = , ycoord = , url = '', radiusofvisibility = 500 where (select count(*) from webcam where url = '') = 0 | Y9: =IF(LEN(K11) > 0, Table13[[#This Row],[Column1]], "")
Q10: 174.746 | X10: ="insert into webcam select name = '"&R19&"', xcoord = "&Q18&", ycoord = "&P17&", url = '"&O16&"', radiusofvisibility = 500 where (select count(*) from webcam where url = '"&O16&"') = 0" -> insert into webcam select name = '', xcoord = , ycoord = , url = '', radiusofvisibility = 500 where (select count(*) from webcam where url = '') = 0 | Y10: =IF(LEN(K12) > 0, Table13[[#This Row],[Column1]], "")
R11: SH16 1 Bond St | X11: ="insert into webcam select name = '"&R20&"', xcoord = "&Q19&", ycoord = "&P18&", url = '"&O17&"', radiusofvisibility = 500 where (select count(*) from webcam where url = '"&O17&"') = 0" -> insert into webcam select name = '', xcoord = , ycoord = , url = '', radiusofvisibility = 500 where (select count(*) from webcam where url = '') = 0 | Y11: =IF(LEN(K13) > 0, Table13[[#This Row],[Column1]], "")
S12: FALSE | X12: ="insert into webcam select name = '"&R21&"', xcoord = "&Q20&", ycoord = "&P19&", url = '"&O18&"', radiusofvisibility = 500 where (select count(*) from webcam where url = '"&O18&"') = 0" -> insert into webcam select name = '', xcoord = , ycoord = , url = '', radiusofvisibility = 500 where (select count(*) from webcam where url = '') = 0 | Y12: =IF(LEN(K14) > 0, Table13[[#This Row],[Column1]], "")
T13: Auckland | X13: ="insert into webcam select name = '"&R22&"', xcoord = "&Q21&", ycoord = "&P20&", url = '"&O19&"', radiusofvisibility = 500 where (select count(*) from webcam where url = '"&O19&"') = 0" -> insert into webcam select name = '', xcoord = , ycoord = , url = '', radiusofvisibility = 500 where (select count(*) from webcam where url = '') = 0 | Y13: =IF(LEN(K15) > 0, Table13[[#This Row],[Column1]], "")
U14: http://www.trafficnz.info/camera/thumb/130.jpg | X14: ="insert into webcam select name = '"&R23&"', xcoord = "&Q22&", ycoord = "&P21&", url = '"&O20&"', radiusofvisibility = 500 where (select count(*) from webcam where url = '"&O20&"') = 0" -> insert into webcam select name = '', xcoord = , ycoord = , url = '', radiusofvisibility = 500 where (select count(*) from webcam where url = '') = 0 | Y14: =IF(LEN(K16) > 0, Table13[[#This Row],[Column1]], "")
V15: FALSE | X15: ="insert into webcam select name = '"&R24&"', xcoord = "&Q23&", ycoord = "&P22&", url = '"&O21&"', radiusofvisibility = 500 where (select count(*) from webcam where url = '"&O21&"') = 0" -> insert into webcam select name = '', xcoord = , ycoord = , url = '', radiusofvisibility = 500 where (select count(*) from webcam where url = '') = 0 | Y15: =IF(LEN(K17) > 0, Table13[[#This Row],[Column1]], "")
